Workbook
Name ______DAT1: #REF!
Name ______DAT1: #REF!
Name ______DAT1: #REF!
Name ______DAT1: #REF!
Name ______DAT2: #REF!
Name ______DAT2: #REF!
Name ______DAT2: #REF!
Name ______DAT2: #REF!
Name ______DAT3: #REF!
Name ______DAT3: #REF!
Name ______DAT3: #REF!
Name ______DAT3: #REF!
Name ______DAT4: #REF!
Name ______DAT4: #REF!
Name ______DAT4: #REF!
Name ______DAT4: #REF!
Name ______DAT5: #REF!
Name ______DAT5: #REF!
Name ______DAT5: #REF!
Name ______DAT5: #REF!
Name ______DAT6: #REF!
Name ______DAT6: #REF!
Name ______DAT6: #REF!
Name ______DAT6: #REF!
Name ______DAT7: #REF!
Name ______DAT7: #REF!
Name ______DAT7: #REF!
Name ______DAT7: #REF!
Name ______DAT8: #REF!
Name ______DAT8: #REF!
Name ______DAT8: #REF!
Name ______DAT8: #REF!
Name _____DAT1: #REF!
Name _____DAT1: #REF!
Name _____DAT1: #REF!
Name _____DAT1: #REF!
Name _____DAT2: #REF!
Name _____DAT2: #REF!
Name _____DAT2: #REF!
Name _____DAT2: #REF!
Name _____DAT3: #REF!
Name _____DAT3: #REF!
Name _____DAT3: #REF!
Name _____DAT3: #REF!
Name _____DAT4: #REF!
Name _____DAT4: #REF!
Name _____DAT4: #REF!
Name _____DAT4: #REF!
Name _____DAT5: #REF!
Name _____DAT5: #REF!
Name _____DAT5: #REF!
Name _____DAT5: #REF!
Name _____DAT6: #REF!
Name _____DAT6: #REF!
Name _____DAT6: #REF!
Name _____DAT6: #REF!
Name _____DAT7: #REF!
Name _____DAT7: #REF!
Name _____DAT7: #REF!
Name _____DAT7: #REF!

Sheet FuzzyLookup_AddIn_Undo_Sheet
A1: Softdel Systems Private Limited
A2: Refund of ITC on Export of Services without payment of taxes
A3: Period: April-25 to September-25
A5: Computation of Refund to be claimed
A6: Tax Head | B6: Turnover of zero rated supply of Goods & Services | C6: Adjusted total Turnover | D6: Net Input tax credit | E6: Maximum refund amount to be claimed
B7: 1 | C7: 2 | D7: 3 | E7: 4 = (1*3)/2
A8: IGST | B8: 286017566 | C8: 306200706 | D8: =SUM(#REF!) -> #REF! | E8: =B8*D8/C8 -> #REF!
A9: CGST
A10: SGST
A12: Total | B12: 286017566 | C12: 306200706 | D12: 11261464 | E12: =E8 -> #REF!
A15: Head | B15: Balance in Credit ledger at the end of tax period for which refund is claim i.e September 25 | C15: Balance in Electronic Credit ledger at the time of filing of refund application | D15: Maximum Refund allowed to be claimed | E15: Refund to be Claimed | F15: Balance available after applying for refund
A16: IGST | B16: 0 | C16: 93683 | D16: =IF(B16>C16,C16,B16) -> 0 | E16: 0 | F16: 0
A17: CGST | B17: 5650921 | C17: 4862011 | D17: =IF(B17>C17,C17,B17) -> 4862011 | F17: 4861746
A18: SGST | B18: 5195231 | C18: 4406323 | D18: =IF(B18>C18,C18,B18) -> 4406323 | F18: 4596559
B19: =SUM(B16:B18) -> 10846152 | C19: =SUM(C16:C18) -> 9362017 | D19: =SUM(D16:D18) -> 9268334 | E19: 0 | F19: 9458305

Sheet Working
A2: Export without payment of tax | G2: Total outward Supply B2B | M2: Total outward Supply Exempt | S2: Credite note | Y2: Total | AE2: Adjusted total Turnover
B3: Taxable value | C3: IGST | D3: CGST | E3: SGST | H3: Taxable value | I3: IGST | J3: CGST | K3: SGST | N3: Taxable value | O3: IGST | P3: CGST | Q3: SGST | T3: Taxable value | U3: IGST | V3: CGST | W3: SGST | Z3: Taxable value | AA3: IGST | AB3: CGST | AC3: SGST | AF3: Taxable value | AG3: IGST | AH3: CGST | AI3: SGST
A4: April | B4: 50268400 | F4: o | G4: April | H4: 3265 | I4: 0 | J4: 293.85 | K4: 293.85 | M4: April | N4: 0 | O4: 0 | P4: 0 | Q4: 0 | S4: April | T4: 7000 | U4: 0 | V4: 630 | W4: 630 | Y4: April | Z4: =B4+H4+N4-T4 -> 50264665 | AA4: =C4+I4+O4-U4 -> 0 | AB4: =D4+J4+P4-V4 -> -336.15 | AC4: =E4+K4+Q4-W4 -> -336.15 | AE4: April | AF4: =B4+H4-T4 -> 50264665 | AG4: =C4+I4+U4 -> 0 | AH4: =D4+J4+V4 -> 923.85 | AI4: =E4+K4+W4 -> 923.85
A5: May | B5: 47861150 | G5: May | H5: 5418956 | I5: 0 | J5: 487706.04 | K5: 487706.04 | L5: x | M5: May | N5: 0 | O5: 0 | P5: 0 | Q5: 0 | S5: May | T5: 0 | U5: 0 | V5: 0 | W5: 0 | Y5: May | Z5: =B5+H5+N5-T5 -> 53280106 | AA5: =C5+I5+O5-U5 -> 0 | AB5: =D5+J5+P5-V5 -> 487706.04 | AC5: =E5+K5+Q5-W5 -> 487706.04 | AE5: May | AF5: =B5+H5-T5 -> 53280106 | AG5: =C5+I5+U5 -> 0 | AH5: =D5+J5+V5 -> 487706.04 | AI5: =E5+K5+W5 -> 487706.04
A6: June | B6: 41651400 | G6: June | H6: 3629285 | I6: 0 | J6: 326635.65 | K6: 326635.65 | M6: June | N6: 12980000 | O6: 0 | P6: 0 | Q6: 0 | R6: x | S6: June | T6: 0 | U6: 0 | V6: 0 | W6: 0 | Y6: June | Z6: =B6+H6+N6-T6 -> 58260685 | AA6: =C6+I6+O6-U6 -> 0 | AB6: =D6+J6+P6-V6 -> 326635.65 | AC6: =E6+K6+Q6-W6 -> 326635.65 | AE6: June | AF6: =B6+H6-T6 -> 45280685 | AG6: =C6+I6+U6 -> 0 | AH6: =D6+J6+V6 -> 326635.65 | AI6: =E6+K6+W6 -> 326635.65
A7: July | B7: 45000950 | G7: July | H7: 2656980 | I7: 91216.8 | J7: 193519.8 | K7: 193519.8 | M7: July | N7: 11800000 | O7: 0 | P7: 0 | Q7: 0 | S7: July | T7: 0 | U7: 0 | V7: 0 | W7: 0 | X7: x | Y7: July | Z7: =B7+H7+N7-T7 -> 59457930 | AA7: =C7+I7+O7-U7 -> 91216.8 | AB7: =D7+J7+P7-V7 -> 193519.8 | AC7: =E7+K7+Q7-W7 -> 193519.8 | AE7: July | AF7: =B7+H7-T7 -> 47657930 | AG7: =C7+I7+U7 -> 91216.8 | AH7: =D7+J7+V7 -> 193519.8 | AI7: =E7+K7+W7 -> 193519.8
A8: Aug | B8: 50676633 | G8: Aug | H8: 3184838 | I8: 78687.36 | J8: 247291.74 | K8: 247291.74 | M8: Aug | N8: 0 | O8: 0 | P8: 0 | Q8: 0 | S8: Aug | T8: 0 | U8: 0 | V8: 0 | W8: 0 | Y8: Aug | Z8: =B8+H8+N8-T8 -> 53861471 | AA8: =C8+I8+O8-U8 -> 78687.36 | AB8: =D8+J8+P8-V8 -> 247291.74 | AC8: =E8+K8+Q8-W8 -> 247291.74 | AD8: x | AE8: Aug | AF8: =B8+H8-T8 -> 53861471 | AG8: =C8+I8+U8 -> 78687.36 | AH8: =D8+J8+V8 -> 247291.74 | AI8: =E8+K8+W8 -> 247291.74
A9: Sep | B9: 50559033 | G9: Sep | H9: 5296816 | I9: 182554.56 | J9: 385436.16 | K9: 385436.16 | M9: Sep | N9: 21706541 | O9: 0 | P9: 0 | Q9: 0 | S9: Sep | T9: 0 | U9: 0 | V9: 0 | W9: 0 | Y9: Sep | Z9: =B9+H9+N9-T9 -> 77562390 | AA9: =C9+I9+O9-U9 -> 182554.56 | AB9: =D9+J9+P9-V9 -> 385436.16 | AC9: =E9+K9+Q9-W9 -> 385436.16 | AE9: Sep | AF9: =B9+H9-T9 -> 55855849 | AG9: =C9+I9+U9 -> 182554.56 | AH9: =D9+J9+V9 -> 385436.16 | AI9: =E9+K9+W9 -> 385436.16
B10: =SUM(B4:B9) -> 286017566 | C10: =SUM(C4:C9) -> 0 | D10: =SUM(D4:D9) -> 0 | E10: =SUM(E4:E9) -> 0 | H10: =SUM(H4:H9) -> 20190140 | I10: =SUM(I4:I9) -> 352458.72 | J10: =SUM(J4:J9) -> 1640883.2 | K10: =SUM(K4:K9) -> 1640883.2 | N10: =SUM(N4:N9) -> 46486541 | O10: =SUM(O4:O9) -> 0 | P10: =SUM(P4:P9) -> 0 | Q10: =SUM(Q4:Q9) -> 0 | T10: =SUM(T4:T9) -> 7000 | U10: =SUM(U4:U9) -> 0 | V10: =SUM(V4:V9) -> 630 | W10: =SUM(W4:W9) -> 630 | Z10: =SUM(Z4:Z9) -> 352687247 | AA10: =SUM(AA4:AA9) -> 352458.72 | AB10: =SUM(AB4:AB9) -> 1640253.2 | AC10: =SUM(AC4:AC9) -> 1640253.2 | AF10: =SUM(AF4:AF9) -> 306200706 | AG10: =SUM(AG4:AG9) -> 352458.72 | AH10: =SUM(AH4:AH9) -> 1641513.2 | AI10: =SUM(AI4:AI9) -> 1641513.2
AA11: 352458.72 | AB11: 1640253.2 | AC11: 1640253.2
AA12: =AA10-AA11 -> 0 | AB12: =AB10-AB11 -> 0 | AC12: =AC10-AC11 -> 0 | AG12: =AG10-AA11 -> 0 | AH12: =AH10-AB11 -> 1260 | AI12: =AI10-AC11 -> 1260
B13: Net Input tax credit
B14: IGST | C14: CGST | D14: SGST
A15: April | B15: 298393 | C15: 834858 | D15: 834858 | E15: o
A16: May | B16: 301365.25 | C16: 592983.28 | D16: 592983.28
A17: June | B17: 142598 | C17: 872360 | D17: 872360
A18: July | B18: -18581 | C18: 711279 | D18: 711279
A19: Aug | B19: 382768 | C19: 789175 | D19: 789175
A20: Sep | B20: 291986 | C20: 1130812 | D20: 1130812
B21: =SUM(B15:B20) -> 1398529.2 | C21: =SUM(C15:C20) -> 4931467.3 | D21: =SUM(D15:D20) -> 4931467.3 | E21: =SUM(B21:D21) -> 11261464
E22: 11261464

Sheet Max Refund can be claimed
A1: Softdel Systems Private Limited
A2: Refund of ITC on Export of Services without payment of taxes
A3: Period: October 25 to December-25
A5: Computation of Refund to be claimed
A6: Tax Head | B6: Turnover of zero rated supply of Goods & Services | C6: Adjusted total Turnover | D6: Net Input tax credit | E6: Maximum refund amount to be claimed
B7: 1 | C7: 2 | D7: 3 | E7: 4 = (1*3)/2
A8: IGST | B8: ='Export Turnover'!B17 -> 125640150 | C8: ='Adjusted Total Turnover'!B20 -> 134502707 | D8: ='ITC summery'!E31 -> 5953626.5 | E8: =B8*D8/C8 -> 5561334.3
A9: CGST
A10: SGST
A12: Total | B12: =B8 -> 125640150 | C12: =C8 -> 134502707 | D12: =D8 -> 5953626.5 | E12: =E8 -> 5561334.3
A15: Head | B15: Balance in Credit ledger at the end of tax period for which refund is claim i.e December 25 | C15: Balance in Electronic Credit ledger at the time of filing of refund application | D15: Maximum Refund allowed to be claimed | E15: Refund to be Claimed | F15: Balance available after applying for refund
A16: IGST | B16: 0 | D16: =IF(B16>C16,C16,B16) -> 0 | E16: 0 | F16: 0
A17: CGST | B17: 6446379 | C17: 4206109 | D17: =MIN(IF(B17>C17,C17,B17),E8/2) -> 2780667.2 | E17: =MIN(D17,C17)-305000 -> 2475667.2 | F17: =C17-E17 -> 1730441.8
A18: SGST | B18: 5543095 | C18: 2781300 | D18: =MIN(IF(B18>C18,C18,B18),E8/2) -> 2780667.2 | E18: =MIN(D18,C18)-305000 -> 2475667.2 | F18: =C18-E18 -> 305632.83
B19: =SUM(B16:B18) -> 11989474 | C19: =SUM(C16:C18) -> 6987409 | D19: =SUM(D16:D18) -> 5561334.3 | E19: =SUM(E16:E18) -> 4951334.3 | F19: =SUM(F16:F18) -> 2036074.7

Sheet SR Oct-25 to Dec-25
A1: Softdel System Limited Refund Working
A2: Sales Register
A3: Period: October-25 to December-25
L4: =SUBTOTAL(9,L6:L1048576) -> 148053420 | N4: =SUBTOTAL(9,N6:N1048576) -> 0 | O4: =SUBTOTAL(9,O6:O1048576) -> 0 | P4: =SUBTOTAL(9,P6:P1048576) -> 0 | Q4: =SUBTOTAL(9,Q6:Q1048576) -> 148053420
A5: Month | B5: Invoice No | C5: Invoice Date | D5: Customer Name | E5: Type of Supply | F5: Place of Supply | G5: GSTIN | H5: HSN/ SAC | I5: Currency | J5: Exchange Rate | K5: Amt in Foreign Currency | L5: Taxable Value | M5: Rate | N5: IGST | O5: CGST | P5: SGST | Q5: Invoice Value | R5: Remark-1 | S5: Type of Supply | T5: Adjusted Turnover (AT) | U5: Zero Rated Turnover (ZRT) | V5: Client Remarks
A6: 45931 | B6: SSPL/10-25Dom/01 | C6: 45937 | D6: KONE Elevator India Private Limited | E6: B2B | F6: India | G6: 27AAACK2567P1Z1 | H6: 998313 | L6: 366850 | M6: 0.18 | N6: 0 | O6: 33016.5 | P6: 33016.5 | Q6: 432883 | R6: Domestic Sales | S6: 1. Domestic Sales | T6: Considered in AT | U6: Not Considered in ZRT
A7: 45931 | B7: SSPL/10-25RoE/1 | C7: 45961 | D7: Asset Vantage Systems Private Limited for cost sharing (asset) | E7: B2B | F7: India | G7: 27AALCS2597J1ZO | H7: 998599 | L7: 631659 | M7: 0.18 | N7: 0 | O7: 56849.31 | P7: 56849.31 | Q7: 745357.62 | R7: Domestic Sales | S7: 1. Domestic Sales | T7: Considered in AT | U7: Not Considered in ZRT
A8: 45931 | B8: SSPL/10-25RoE/2 | C8: 45961 | D8: Asset Vantage Systems Private Limited for cost sharing (asset) | E8: B2B | F8: India | G8: 27AALCS2597J1ZO | H8: 998599 | L8: 753661 | M8: 0.18 | N8: 0 | O8: 67829.49 | P8: 67829.49 | Q8: 889319.98 | R8: Domestic Sales | S8: 1. Domestic Sales | T8: Considered in AT | U8: Not Considered in ZRT
A9: 45931 | B9: SSPL/10-25RoE/3 | C9: 45961 | D9: Unidel Technologies LLP for cost sharing (Liab) | E9: B2B | F9: India | G9: 27AAEFU8529J1ZN | H9: 998599 | L9: 21000 | M9: 0.18 | N9: 0 | O9: 1890 | P9: 1890 | Q9: 24780 | R9: Domestic Sales | S9: 1. Domestic Sales | T9: Considered in AT | U9: Not Considered in ZRT
A10: 45931 | B10: SSPL/10-25RoE/4 | C10: 45961 | D10: Asset Vantage Systems Private Limited for cost sharing (asset) | E10: B2B | F10: India | G10: 27AALCS2597J1ZO | H10: 998519 | L10: 1221286 | M10: 0.18 | N10: 0 | O10: 109915.74 | P10: 109915.74 | Q10: 1441117.5 | R10: Domestic Sales | S10: 1. Domestic Sales | T10: Considered in AT | U10: Not Considered in ZRT
A11: 45931 | B11: SSPL/10-25RoE/5 | C11: 45961 | D11: Unidel Technologies LLP for cost sharing (Liab) | E11: B2B | F11: India | G11: 27AAEFU8529J1ZN | H11: 998519 | L11: 3771 | M11: 0.18 | N11: 0 | O11: 339.39 | P11: 339.39 | Q11: 4449.78 | R11: Domestic Sales | S11: 1. Domestic Sales | T11: Considered in AT | U11: Not Considered in ZRT
A12: 45931 | B12: SSPL/10-25EX/1 | C12: 45961 | D12: SS USA Inc | E12: Export - Without payment of tax | F12: USA | H12: 998313 | I12: USD | J12: 88.5696 | K12: 200000 | L12: 17713920 | M12: 0 | N12: 0 | O12: 0 | P12: 0 | Q12: 17713920 | R12: Export - Without payment of tax | S12: 3. Export - Without payment of tax | T12: Considered in AT | U12: Considered in ZRT
A13: 45931 | B13: SSPL/10-25EX/2 | C13: 45961 | D13: SS USA Inc | E13: Export - Without payment of tax | F13: USA | H13: 998313 | I13: USD | J13: 88.5696 | K13: 150000 | L13: 13285440 | M13: 0 | N13: 0 | O13: 0 | P13: 0 | Q13: 13285440 | R13: Export - Without payment of tax | S13: 3. Export - Without payment of tax | T13: Considered in AT | U13: Considered in ZRT
A14: 45931 | B14: SSPL/10-25EX/3 | C14: 45961 | D14: SS USA Inc | E14: Export - Without payment of tax | F14: USA | H14: 998313 | I14: USD | J14: 88.5696 | K14: 130000 | L14: 11514048 | M14: 0 | N14: 0 | O14: 0 | P14: 0 | Q14: 11514048 | R14: Export - Without payment of tax | S14: 3. Export - Without payment of tax | T14: Considered in AT | U14: Considered in ZRT
A15: 45931 | B15: SSPL/10-25EX/4 | C15: 45961 | D15: SS USA Inc | E15: Export - Without payment of tax | F15: USA | H15: 998313 | I15: USD | J15: 88.5696 | K15: 100000 | L15: 8856960 | M15: 0 | N15: 0 | O15: 0 | P15: 0 | Q15: 8856960 | R15: Export - Without payment of tax | S15: 3. Export - Without payment of tax | T15: Considered in AT | U15: Considered in ZRT
A16: 45931 | B16: SSPL/10-25EX/5 | C16: 45961 | D16: Softdel Systems Private Limited JBO | E16: Exempted | F16: Japan | H16: 998313 | L16: 5800000 | M16: 0 | N16: 0 | O16: 0 | P16: 0 | Q16: 5800000 | R16: Exempt Sales | S16: 2. Exempt Sales | T16: Not Considered in AT | U16: Not Considered in ZRT
A17: 45931 | B17: SSPL/10-25EX/6 | C17: 45961 | D17: Softdel Systems Private Limited JBO | E17: Exempted | F17: Japan | H17: 998313 | L17: 4060000 | M17: 0 | N17: 0 | O17: 0 | P17: 0 | Q17: 4060000 | R17: Exempt Sales | S17: 2. Exempt Sales | T17: Not Considered in AT | U17: Not Considered in ZRT
A18: 45962 | B18: SSPL/11-25Dom/1 | C18: 45966 | D18: KONE Elevator India Private Limited | E18: B2B | F18: India | G18: 27AAACK2567P1Z1 | H18: 998313 | L18: 333500 | M18: 0.18 | N18: 0 | O18: 30015 | P18: 30015 | Q18: 393530 | R18: Domestic Sales | S18: 1. Domestic Sales | T18: Considered in AT | U18: Not Considered in ZRT
A19: 45962 | B19: SSPL/11-25Dom/2 | C19: 45985 | D19: Danfoss Industries Private Limited | E19: B2B | F19: India | G19: 33AABCD0321M1Z4 | H19: 998313 | L19: 250000 | M19: 0.18 | N19: 45000 | O19: 0 | P19: 0 | Q19: 295000 | R19: Domestic Sales | S19: 1. Domestic Sales | T19: Considered in AT | U19: Not Considered in ZRT
A20: 45962 | B20: SSPL/11-25RoE/1 | C20: 45991 | D20: Unidel Technologies LLP for cost sharing (Liab) | E20: B2B | F20: India | G20: 27AAEFU8529J1ZN | H20: 998599 | L20: 13000 | M20: 0.18 | N20: 0 | O20: 1170 | P20: 1170 | Q20: 15340 | R20: Domestic Sales | S20: 1. Domestic Sales | T20: Considered in AT | U20: Not Considered in ZRT
A21: 45962 | B21: SSPL/11-25RoE/2 | C21: 45991 | D21: Asset Vantage Systems Private Limited for cost sharing (asset) | E21: B2B | F21: India | G21: 27AALCS2597J1ZO | H21: 998599 | L21: 753661 | M21: 0.18 | N21: 0 | O21: 67829.49 | P21: 67829.49 | Q21: 889319.98 | R21: Domestic Sales | S21: 1. Domestic Sales | T21: Considered in AT | U21: Not Considered in ZRT
A22: 45962 | B22: SSPL/11-25RoE/3 | C22: 45991 | D22: Asset Vantage Systems Private Limited for cost sharing (asset) | E22: B2B | F22: India | G22: 27AALCS2597J1ZO | H22: 998599 | L22: 1198548 | M22: 0.18 | N22: 0 | O22: 107869.32 | P22: 107869.32 | Q22: 1414286.6 | R22: Domestic Sales | S22: 1. Domestic Sales | T22: Considered in AT | U22: Not Considered in ZRT
A23: 45962 | B23: SSPL/11-25RoE/4 | C23: 45991 | D23: Unidel Technologies LLP for cost sharing (Liab) | E23: B2B | F23: India | G23: 27AAEFU8529J1ZN | H23: 998519 | L23: 3771 | M23: 0.18 | N23: 0 | O23: 339.39 | P23: 339.39 | Q23: 4449.78 | R23: Domestic Sales | S23: 1. Domestic Sales | T23: Considered in AT | U23: Not Considered in ZRT
A24: 45962 | B24: SSPL/11-25RoE/5 | C24: 45991 | D24: Asset Vantage Systems Private Limited for cost sharing (asset) | E24: B2B | F24: India | G24: 27AALCS2597J1ZO | H24: 998599 | L24: 433754 | M24: 0.18 | N24: 0 | O24: 39037.86 | P24: 39037.86 | Q24: 511829.72 | R24: Domestic Sales | S24: 1. Domestic Sales | T24: Considered in AT | U24: Not Considered in ZRT
A25: 45962 | B25: SSPL/11-25EX/1 | C25: 45978 | D25: SS USA Inc | E25: Export - Without payment of tax | F25: USA | H25: 998313 | I25: USD | J25: 88.6525 | K25: 80000 | L25: 7092200 | M25: 0 | N25: 0 | O25: 0 | P25: 0 | Q25: 7092200 | R25: Export - Without payment of tax | S25: 3. Export - Without payment of tax | T25: Considered in AT | U25: Considered in ZRT
A26: 45962 | B26: SSPL/11-25EX/2 | C26: 45991 | D26: SS USA Inc | E26: Export - Without payment of tax | F26: USA | H26: 998313 | I26: USD | J26: 89.3476 | K26: 200000 | L26: 17869520 | M26: 0 | N26: 0 | O26: 0 | P26: 0 | Q26: 17869520 | R26: Export - Without payment of tax | S26: 3. Export - Without payment of tax | T26: Considered in AT | U26: Considered in ZRT
A27: 45962 | B27: SSPL/11-25EX/3 | C27: 45991 | D27: SS USA Inc | E27: Export - Without payment of tax | F27: USA | H27: 998313 | I27: USD | J27: 89.3476 | K27: 150000 | L27: 13402140 | M27: 0 | N27: 0 | O27: 0 | P27: 0 | Q27: 13402140 | R27: Export - Without payment of tax | S27: 3. Export - Without payment of tax | T27: Considered in AT | U27: Considered in ZRT
A28: 45962 | B28: SSPL/11-25EX/4 | C28: 45991 | D28: SS USA Inc | E28: Export - Without payment of tax | F28: USA | H28: 998313 | I28: USD | J28: 89.3476 | K28: 150000 | L28: 13402140 | M28: 0 | N28: 0 | O28: 0 | P28: 0 | Q28: 13402140 | R28: Export - Without payment of tax | S28: 3. Export - Without payment of tax | T28: Considered in AT | U28: Considered in ZRT
A29: 45962 | B29: SSPL/11-25EX/5 | C29: 45991 | D29: Softdel Systems Private Limited JBO | E29: Exempted | F29: Japan | H29: 998313 | L29: 5700000 | M29: 0 | N29: 0 | O29: 0 | P29: 0 | Q29: 5700000 | R29: Exempt Sales | S29: 2. Exempt Sales | T29: Not Considered in AT | U29: Not Considered in ZRT
A30: 45992 | B30: SSPL/12-25Dom/1 | C30: 45994 | D30: KONE Elevator India Private Limited | E30: B2B | F30: India | G30: 27AAACK2567P1Z1 | H30: 998313 | L30: 333500 | M30: 0.18 | N30: 0 | O30: 30015 | P30: 30015 | Q30: 393530 | R30: Domestic Sales | S30: 1. Domestic Sales | T30: Considered in AT | U30: Not Considered in ZRT
A31: 45992 | B31: SSPL/12-25Dom/2 | C31: 46013 | D31: San Telequip Pvt Ltd | E31: B2B | F31: India | G31: 27AACCS9541B1ZG | H31: 997731 | L31: 195000 | M31: 0.18 | N31: 0 | O31: 17550 | P31: 17550 | Q31: 230100 | R31: Domestic Sales | S31: 1. Domestic Sales | T31: Considered in AT | U31: Not Considered in ZRT
A32: 45992 | B32: SSPL/12-25Dom/3 | C32: 46020 | D32: KONE Elevator India Private Limited | E32: B2B | F32: India | G32: 27AAACK2567P1Z1 | H32: 998313 | L32: 816640 | M32: 0.18 | N32: 0 | O32: 73497.6 | P32: 73497.6 | Q32: 963635.2 | R32: Domestic Sales | S32: 1. Domestic Sales | T32: Considered in AT | U32: Not Considered in ZRT
A33: 45992 | B33: SSPL/12-25RoE/1 | C33: 46022 | D33: Asset Vantage Systems Private Limited for cost sharing (asset) | E33: B2B | F33: India | G33: 27AALCS2597J1ZO | H33: 998599 | L33: 394433 | M33: 0.18 | N33: 0 | O33: 35498.97 | P33: 35498.97 | Q33: 465430.94 | R33: Domestic Sales | S33: 1. Domestic Sales | T33: Considered in AT | U33: Not Considered in ZRT
A34: 45992 | B34: SSPL/12-25RoE/2 | C34: 46022 | D34: Asset Vantage Systems Private Limited for cost sharing (asset) | E34: B2B | F34: India | G34: 27AALCS2597J1ZO | H34: 998599 | L34: 1197727 | M34: 0.18 | N34: 0 | O34: 107795.43 | P34: 107795.43 | Q34: 1413317.9 | R34: Domestic Sales | S34: 1. Domestic Sales | T34: Considered in AT | U34: Not Considered in ZRT
A35: 45992 | B35: SSPL/12-25RoE/3 | C35: 46022 | D35: Unidel Technologies LLP for cost sharing (Liab) | E35: B2B | F35: India | G35: 27AAEFU8529J1ZN | H35: 998519 | L35: 3775 | M35: 0.18 | N35: 0 | O35: 339.75 | P35: 339.75 | Q35: 4454.5 | R35: Domestic Sales | S35: 1. Domestic Sales | T35: Considered in AT | U35: Not Considered in ZRT
A36: 45992 | B36: SSPL/12-25RoE/4 | C36: 46022 | D36: Asset Vantage Systems Private Limited for cost sharing (asset) | E36: B2B | F36: India | G36: 27AALCS2597J1ZO | H36: 998599 | L36: 753661 | M36: 0.18 | N36: 0 | O36: 67829.49 | P36: 67829.49 | Q36: 889319.98 | R36: Domestic Sales | S36: 1. Domestic Sales | T36: Considered in AT | U36: Not Considered in ZRT
A37: 45992 | B37: SSPL/12-25EX/1 | C37: 46022 | D37: SS USA Inc | E37: Export - Without payment of tax | F37: USA | H37: 998313 | I37: USD | J37: 89.83 | K37: 120000 | L37: 10779600 | M37: 0 | N37: 0 | O37: 0 | P37: 0 | Q37: 10779600 | R37: Export - Without payment of tax | S37: 3. Export - Without payment of tax | T37: Considered in AT | U37: Considered in ZRT
A38: 45992 | B38: SSPL/12-25EX/2 | C38: 46022 | D38: SS USA Inc | E38: Export - Without payment of tax | F38: USA | H38: 998313 | I38: USD | J38: 89.8354 | K38: 120000 | L38: 10780248 | M38: 0 | N38: 0 | O38: 0 | P38: 0 | Q38: 10780248 | R38: Export - Without payment of tax | S38: 3. Export - Without payment of tax | T38: Considered in AT | U38: Considered in ZRT
A39: 45992 | B39: SSPL/12-25EX/3 | C39: 46022 | D39: SS USA Inc | E39: Export - Without payment of tax | F39: USA | H39: 998313 | I39: USD | J39: 89.8354 | K39: 130000 | L39: 11678602 | M39: 0 | N39: 0 | O39: 0 | P39: 0 | Q39: 11678602 | R39: Export - Without payment of tax | S39: 3. Export - Without payment of tax | T39: Considered in AT | U39: Considered in ZRT
A40: 45992 | B40: SSPL/12-25EX/4 | C40: 46022 | D40: SS USA Inc | E40: Export - Without payment of tax | F40: USA | H40: 998313 | I40: USD | J40: 89.8354 | K40: 130000 | L40: 11678602 | M40: 0 | N40: 0 | O40: 0 | P40: 0 | Q40: 11678602 | R40: Export - Without payment of tax | S40: 3. Export - Without payment of tax | T40: Considered in AT | U40: Considered in ZRT
...

Sheet Sales Summary
A1: Softdel System Private Limited
A2: Sales Summary
A3: Period: Oct-25 to Dec-25
A4: Sales as per Sales registered
A5: Row Labels | B5: Sum of Taxable Value | C5: Sum of IGST | D5: Sum of CGST | E5: Sum of SGST
A6: 1. Domestic Sales | B6: 9679197 | C6: 45000 | D6: 848627.73 | E6: 848627.73
A7: 2. Exempt Sales | B7: 26000000 | C7: 0 | D7: 0 | E7: 0
A8: 3. Export - Without payment of tax | B8: 148053420 | C8: 0 | D8: 0 | E8: 0
A9: 4. B2B Credit Note | B9: -816640 | C9: 0 | D9: -73497.6 | E9: -73497.6
A10: Grand Total | B10: 182915977 | C10: 45000 | D10: 775130.13 | E10: 775130.13
A12: Sales as per GSTR-1
A13: Type of Sales | B13: Sum of Taxable Value | C13: Sum of IGST | D13: Sum of CGST | E13: Sum of SGST
A14: 1. Domestic Sales | B14: ='Monthly Return Summary'!R5 -> 9679197 | C14: ='Monthly Return Summary'!S5 -> 45000 | D14: ='Monthly Return Summary'!T5 -> 848627.73 | E14: ='Monthly Return Summary'!U5 -> 848627.73
A15: 2. Exempt Sales (Net of Credit Notes) | B15: ='Monthly Return Summary'!R6 -> 26000000 | C15: ='Monthly Return Summary'!S6 -> 0 | D15: ='Monthly Return Summary'!T6 -> 0 | E15: ='Monthly Return Summary'!U6 -> 0
A16: 3. Export Sales (WOP) - (Net of Credit Notes) | B16: ='Monthly Return Summary'!R7 -> 148053420 | C16: ='Monthly Return Summary'!S7 -> 0 | D16: ='Monthly Return Summary'!T7 -> 0 | E16: ='Monthly Return Summary'!U7 -> 0
A17: 4. Credit note - B2B | B17: ='Monthly Return Summary'!R8 -> -816640 | C17: ='Monthly Return Summary'!S8 -> 0 | D17: ='Monthly Return Summary'!T8 -> -73497.6 | E17: ='Monthly Return Summary'!U8 -> -73497.6
A18: 5. SEZ - Without payment of tax | B18: ='Monthly Return Summary'!R9 -> 0 | C18: ='Monthly Return Summary'!S9 -> 0 | D18: ='Monthly Return Summary'!T9 -> 0 | E18: ='Monthly Return Summary'!U9 -> 0
A19: Grand Total | B19: =SUM(B14:B17) -> 182915977 | C19: =SUM(C14:C17) -> 45000 | D19: =SUM(D14:D17) -> 775130.13 | E19: =SUM(E14:E17) -> 775130.13
A21: Sales as per GSTR-3B
A22: Type of Sales | B22: Sum of Taxable Value | C22: Sum of IGST | D22: Sum of CGST | E22: Sum of SGST
A23: 1. Outward supplies (other than zero rated, nil rated and exempted) | B23: ='Monthly Return Summary'!R14 -> 8862557 | C23: ='Monthly Return Summary'!S14 -> 45000 | D23: ='Monthly Return Summary'!T14 -> 775130.49 | E23: ='Monthly Return Summary'!U14 -> 775130.49
A24: 2. Outward taxable supplies (zero rated) | B24: ='Monthly Return Summary'!R15 -> 148053420 | C24: ='Monthly Return Summary'!S15 -> 0 | D24: ='Monthly Return Summary'!T15 -> 0 | E24: ='Monthly Return Summary'!U15 -> 0
A25: 3. Other outward supplies (nil rated, exempted) | B25: ='Monthly Return Summary'!R16 -> 26000000 | C25: ='Monthly Return Summary'!S16 -> 0 | D25: ='Monthly Return Summary'!T16 -> 0 | E25: ='Monthly Return Summary'!U16 -> 0
A26: Grand Total | B26: =SUM(B23:B25) -> 182915977 | C26: =SUM(C23:C25) -> 45000 | D26: =SUM(D23:D25) -> 775130.49 | E26: =SUM(E23:E25) -> 775130.49
A28: Difference (GSTR-3B-GSTR-1)
A29: Type of Sales | B29: Sum of Taxable Value | C29: Sum of IGST | D29: Sum of CGST | E29: Sum of SGST
A30: Difference (GSTR-3B-GSTR-1) | B30: =B26-B19 -> 0 | C30: =C26-C19 -> 0 | D30: =D26-D19 -> 0.36 | E30: =E26-E19 -> 0.36
A31: Grand Total | B31: =B30 -> 0 | C31: =C30 -> 0 | D31: =D30 -> 0.36 | E31: =E30 -> 0.36

Sheet Adjusted Total Turnover
A1: Softdel System Limited Refund Working
A2: Sales Register
A3: Period: October-25 to December-25
A5: Sales as per GSTR-1
A6: Type of Sales | B6: Sum of Taxable Value | C6: Sum of IGST | D6: Sum of CGST | E6: Sum of SGST
A7: 1. Domestic Sales (Net of Credit Notes) | B7: ='Sales Summary'!B6+'Sales Summary'!B9 -> 8862557 | C7: ='Sales Summary'!C6+'Sales Summary'!C9 -> 45000 | D7: ='Sales Summary'!D6+'Sales Summary'!D9 -> 775130.13 | E7: ='Sales Summary'!E6+'Sales Summary'!E9 -> 775130.13
A8: 2. Exempt Sales (Net of Credit Notes) | B8: ='Sales Summary'!B7 -> 26000000 | C8: ='Sales Summary'!C7 -> 0 | D8: ='Sales Summary'!D7 -> 0 | E8: ='Sales Summary'!E7 -> 0
A9: 3. Export- Without payment of tax | B9: ='Sales Summary'!B8 -> 148053420 | C9: ='Sales Summary'!C8 -> 0 | D9: ='Sales Summary'!D8 -> 0 | E9: ='Sales Summary'!E8 -> 0
A10: Grand Total | B10: =SUM(B7:B9) -> 182915977 | C10: =SUM(C7:C9) -> 45000 | D10: =SUM(D7:D9) -> 775130.13 | E10: =SUM(E7:E9) -> 775130.13
A14: Supplies excluded for the calculation of "Adjusted Total Turnover"
A15: - Exempt Supplies | B15: =B8 -> 26000000 | C15: =C8 -> 0 | D15: =D8 -> 0 | E15: =E8 -> 0
A16: - Total export supplies to SS USA Inc whose amount received onwards September 2025 | B16: ='Export sales'!Z2 -> 148053420 | C16: ='Export sales'!AA2 -> 0 | D16: ='Export sales'!AB2 -> 0 | E16: ='Export sales'!AC2 -> 0
A18: Supplies Added for the calculation of "Adjusted Total Turnover"
A19: + Export - (WOP) - Pertains to October 24 to March 25- Amount received during current period | B19: ='Export Turnover'!B16 -> 125640150 | C19: 0 | D19: 0 | E19: 0
A20: Adjusted Total Turnover | B20: =B10-B15-B16+B19 -> 134502707 | C20: =C10-C15 -> 45000 | D20: =D10-D15 -> 775130.13 | E20: =E10-E15 -> 775130.13

Sheet Export Turnover
A1: Softdel System Limited Refund Working
A2: Sales Register
A3: Period: April-25 to September-25
A5: Sales Register
A6: Row Labels | B6: Sum of Taxable Value | C6: Sum of IGST
A7: SS USA Inc | B7: 148053420 | C7: 0
A8: Export - Without payment of tax | B8: 148053420 | C8: 0
A9: Grand Total | B9: 148053420 | C9: 0
A11: Supplies excluded for the calculation of "Export Turnover"
A13: - Total export supplies to SS USA Inc whose amount received onwards September 2025 | B13: =B8 -> 148053420 | C13: 0
A15: Supplies Added for the calculation of "Export Turnover"
A16: + Export - (WOP) - Pertains to October 24 to June 25- Amount received during current period | B16: ='Exp invoics Apr to Sep 25'!X3 -> 125640150 | C16: ='Export sales'!AA2 -> 0
A17: Export Turnover considered for Refund | B17: =B9-B12-B13+B16 -> 125640150 | C17: =C9-C12-C13+C16 -> 0

Sheet Export sales
A1: Softdel System Limited Refund Working | J1: Yellow invoice to singapore | Y1: Row Labels | Z1: Sum of Taxable Value | AA1: Sum of IGST | AB1: Sum of CGST | AC1: Sum of SGST
A2: Sales Register | J2: Invoices are not avalible with us | Y2: Not Considered in ZRT | Z2: 148053420 | AA2: 0 | AB2: 0 | AC2: 0
A3: Period: Oct-25 to Dec-25 | Y3: Grand Total | Z3: 148053420 | AA3: 0 | AB3: 0 | AC3: 0
L4: =SUBTOTAL(9,L6:L17) -> 148053420 | M4: =SUBTOTAL(9,M6:M17) -> 0 | N4: =SUBTOTAL(9,N6:N17) -> 0 | O4: =SUBTOTAL(9,O6:O17) -> 0 | P4: =SUBTOTAL(9,P6:P17) -> 0 | Q4: =SUBTOTAL(9,Q6:Q17) -> 148053420
A5: Month | B5: Invoice No | C5: Invoice Date | D5: Customer Name | E5: Type of Supply | F5: Place of Supply | G5: Customer GSTIN | H5: HSN/ SAC | I5: Currency | J5: Exchange Rate | K5: Amt in Foreign Currency | L5: Taxable Value | M5: Rate | N5: IGST | O5: CGST | P5: SGST | Q5: Invoice Value | R5: Remark-1 | S5: Type of Supply | T5: Adjusted Turnover (AT) | U5: Zero Rated Turnover (ZRT) | V5: Client Remarks | W5: Client Remarks
A6: 45931 | B6: SSPL/10-25EX/1 | C6: 45961 | D6: SS USA Inc | E6: Export - Without payment of tax | F6: USA | H6: 998313 | I6: USD | J6: 88.5696 | K6: 200000 | L6: 17713920 | M6: 0 | N6: 0 | O6: 0 | P6: 0 | Q6: 17713920 | R6: Export - WOP - Amount received after December | S6: 3. Export - Without payment of tax | T6: Not Considered in AT | U6: Not Considered in ZRT
A7: 45931 | B7: SSPL/10-25EX/2 | C7: 45961 | D7: SS USA Inc | E7: Export - Without payment of tax | F7: USA | H7: 998313 | I7: USD | J7: 88.5696 | K7: 150000 | L7: 13285440 | M7: 0 | N7: 0 | O7: 0 | P7: 0 | Q7: 13285440 | R7: Export - WOP - Amount received after December | S7: 3. Export - Without payment of tax | T7: Not Considered in AT | U7: Not Considered in ZRT
A8: 45931 | B8: SSPL/10-25EX/3 | C8: 45961 | D8: SS USA Inc | E8: Export - Without payment of tax | F8: USA | H8: 998313 | I8: USD | J8: 88.5696 | K8: 130000 | L8: 11514048 | M8: 0 | N8: 0 | O8: 0 | P8: 0 | Q8: 11514048 | R8: Export - WOP - Amount received after December | S8: 3. Export - Without payment of tax | T8: Not Considered in AT | U8: Not Considered in ZRT
A9: 45931 | B9: SSPL/10-25EX/4 | C9: 45961 | D9: SS USA Inc | E9: Export - Without payment of tax | F9: USA | H9: 998313 | I9: USD | J9: 88.5696 | K9: 100000 | L9: 8856960 | M9: 0 | N9: 0 | O9: 0 | P9: 0 | Q9: 8856960 | R9: Export - WOP - Amount received after December | S9: 3. Export - Without payment of tax | T9: Not Considered in AT | U9: Not Considered in ZRT
A10: 45962 | B10: SSPL/11-25EX/1 | C10: 45978 | D10: SS USA Inc | E10: Export - Without payment of tax | F10: USA | H10: 998313 | I10: USD | J10: 88.6525 | K10: 80000 | L10: 7092200 | M10: 0 | N10: 0 | O10: 0 | P10: 0 | Q10: 7092200 | R10: Export - WOP - Amount received after December | S10: 3. Export - Without payment of tax | T10: Not Considered in AT | U10: Not Considered in ZRT
A11: 45962 | B11: SSPL/11-25EX/2 | C11: 45991 | D11: SS USA Inc | E11: Export - Without payment of tax | F11: USA | H11: 998313 | I11: USD | J11: 89.3476 | K11: 200000 | L11: 17869520 | M11: 0 | N11: 0 | O11: 0 | P11: 0 | Q11: 17869520 | R11: Export - WOP - Amount received after December | S11: 3. Export - Without payment of tax | T11: Not Considered in AT | U11: Not Considered in ZRT
A12: 45962 | B12: SSPL/11-25EX/3 | C12: 45991 | D12: SS USA Inc | E12: Export - Without payment of tax | F12: USA | H12: 998313 | I12: USD | J12: 89.3476 | K12: 150000 | L12: 13402140 | M12: 0 | N12: 0 | O12: 0 | P12: 0 | Q12: 13402140 | R12: Export - WOP - Amount received after December | S12: 3. Export - Without payment of tax | T12: Not Considered in AT | U12: Not Considered in ZRT
A13: 45962 | B13: SSPL/11-25EX/4 | C13: 45991 | D13: SS USA Inc | E13: Export - Without payment of tax | F13: USA | H13: 998313 | I13: USD | J13: 89.3476 | K13: 150000 | L13: 13402140 | M13: 0 | N13: 0 | O13: 0 | P13: 0 | Q13: 13402140 | R13: Export - WOP - Amount received after December | S13: 3. Export - Without payment of tax | T13: Not Considered in AT | U13: Not Considered in ZRT
A14: 45992 | B14: SSPL/12-25EX/1 | C14: 46022 | D14: SS USA Inc | E14: Export - Without payment of tax | F14: USA | H14: 998313 | I14: USD | J14: 89.83 | K14: 120000 | L14: 10779600 | M14: 0 | N14: 0 | O14: 0 | P14: 0 | Q14: 10779600 | R14: Export - WOP - Amount received after December | S14: 3. Export - Without payment of tax | T14: Not Considered in AT | U14: Not Considered in ZRT
A15: 45992 | B15: SSPL/12-25EX/2 | C15: 46022 | D15: SS USA Inc | E15: Export - Without payment of tax | F15: USA | H15: 998313 | I15: USD | J15: 89.8354 | K15: 120000 | L15: 10780248 | M15: 0 | N15: 0 | O15: 0 | P15: 0 | Q15: 10780248 | R15: Export - WOP - Amount received after December | S15: 3. Export - Without payment of tax | T15: Not Considered in AT | U15: Not Considered in ZRT
A16: 45992 | B16: SSPL/12-25EX/3 | C16: 46022 | D16: SS USA Inc | E16: Export - Without payment of tax | F16: USA | H16: 998313 | I16: USD | J16: 89.8354 | K16: 130000 | L16: 11678602 | M16: 0 | N16: 0 | O16: 0 | P16: 0 | Q16: 11678602 | R16: Export - WOP - Amount received after December | S16: 3. Export - Without payment of tax | T16: Not Considered in AT | U16: Not Considered in ZRT
A17: 45992 | B17: SSPL/12-25EX/4 | C17: 46022 | D17: SS USA Inc | E17: Export - Without payment of tax | F17: USA | H17: 998313 | I17: USD | J17: 89.8354 | K17: 130000 | L17: 11678602 | M17: 0 | N17: 0 | O17: 0 | P17: 0 | Q17: 11678602 | R17: Export - WOP - Amount received after December | S17: 3. Export - Without payment of tax | T17: Not Considered in AT | U17: Not Considered in ZRT

Sheet Exp invoics Apr to Sep 25
W2: Row Labels | X2: Sum of Taxable Value | Y2: Sum of IGST | Z2: Sum of CGST | AA2: Sum of SGST
W3: Considered in ZRT | X3: 125640150 | Y3: 0 | Z3: 0 | AA3: 0
W4: Not Considered in ZRT | X4: 1.3139902e+08 | Y4: 0 | Z4: 0 | AA4: 0
A5: Month | B5: Invoice No | C5: Invoice Date | D5: Customer Name | E5: Type of Supply | F5: Place of Supply | G5: Customer GSTIN | H5: HSN/ SAC | I5: Currency | J5: Exchange Rate | K5: Amt in Foreign Currency | L5: Taxable Value | M5: Rate | N5: IGST | O5: CGST | P5: SGST | Q5: Invoice Value | R5: Type of Supply | S5: Zero Rated Turnover (ZRT) | T5: Client Remarks | W5: Grand Total | X5: 2.5703917e+08 | Y5: 0 | Z5: 0 | AA5: 0
A6: 45748 | B6: SSPL/04-25Ex/04 | C6: 45777 | D6: SS USA Inc | E6: Export - Without payment of tax | F6: USA | G6: Unregistered | H6: 998313 | I6: USD | J6: 85.16 | K6: 120000 | L6: 10219200 | M6: 0 | N6: 0 | O6: 0 | P6: 0 | Q6: 10219200 | R6: Export - WOP - Amount received after September | S6: Considered in ZRT
A7: 45748 | B7: SSPL/04-25Ex/05 | C7: 45777 | D7: SS USA Inc | E7: Export - Without payment of tax | F7: USA | G7: Unregistered | H7: 998313 | I7: USD | J7: 85.16 | K7: 130000 | L7: 11070800 | M7: 0 | N7: 0 | O7: 0 | P7: 0 | Q7: 11070800 | R7: Export - WOP - Amount received after September | S7: Considered in ZRT
A8: 45802 | B8: SSPL/05-25EX/1 | C8: 45806 | D8: SS USA Inc | E8: Export - Without payment of tax | F8: USA | G8: Unregistered | H8: 998313 | I8: USD | J8: 85.42 | K8: 60000 | L8: 5125200 | M8: 0 | N8: 0 | O8: 0 | P8: 0 | Q8: 5125200 | R8: Export - WOP - Amount received after September | S8: Considered in ZRT
A9: 45802 | B9: SSPL/05-25EX/2 | C9: 45808 | D9: SS USA Inc | E9: Export - Without payment of tax | F9: USA | G9: Unregistered | H9: 998313 | I9: USD | J9: 85.4719 | K9: 120000 | L9: 10256628 | M9: 0 | N9: 0 | O9: 0 | P9: 0 | Q9: 10256628 | R9: Export - WOP - Amount received after September | S9: Considered in ZRT
A10: 45802 | B10: SSPL/05-25EX/3 | C10: 45808 | D10: SS USA Inc | E10: Export - Without payment of tax | F10: USA | G10: Unregistered | H10: 998313 | I10: USD | J10: 85.4719 | K10: 120000 | L10: 10256628 | M10: 0 | N10: 0 | O10: 0 | P10: 0 | Q10: 10256628 | R10: Export - WOP - Amount received after September | S10: Considered in ZRT
A11: 45802 | B11: SSPL/05-25EX/4 | C11: 45808 | D11: SS USA Inc | E11: Export - Without payment of tax | F11: USA | G11: Unregistered | H11: 998313 | I11: USD | J11: 85.4719 | K11: 130000 | L11: 11111347 | M11: 0 | N11: 0 | O11: 0 | P11: 0 | Q11: 11111347 | R11: Export - WOP - Amount received after September | S11: Considered in ZRT
A12: 45802 | B12: SSPL/05-25EX/5 | C12: 45808 | D12: SS USA Inc | E12: Export - Without payment of tax | F12: USA | G12: Unregistered | H12: 998313 | I12: USD | J12: 85.4719 | K12: 130000 | L12: 11111347 | M12: 0 | N12: 0 | O12: 0 | P12: 0 | Q12: 11111347 | R12: Export - WOP - Amount received after September | S12: Considered in ZRT
A13: 45809 | B13: SSPL/06-25Ex/1 | C13: 45811 | D13: SS USA Inc | E13: Export - Without payment of tax | F13: USA | G13: Unregistered | H13: 998313 | I13: USD | J13: 85.4 | K13: 175000 | L13: 14945000 | M13: 0 | N13: 0 | O13: 0 | P13: 0 | Q13: 14945000 | R13: Export - WOP - Amount received after September | S13: Considered in ZRT
A14: 45809 | B14: SSPL/06-25EX/2 | C14: 45827 | D14: SS USA Inc | E14: Export - Without payment of tax | F14: USA | G14: Unregistered | H14: 998313 | I14: USD | J14: 86.44 | K14: 110000 | L14: 9508400 | M14: 0 | N14: 0 | O14: 0 | P14: 0 | Q14: 9508400 | R14: Export - WOP - Amount received after September | S14: Considered in ZRT
A15: 45809 | B15: SSPL/06-25EX/3 | C15: 45834 | D15: SS USA Inc | E15: Export - Without payment of tax | F15: USA | G15: Unregistered | H15: 998313 | I15: USD | J15: 85.99 | K15: 200000 | L15: 17198000 | M15: 0 | N15: 0 | O15: 0 | P15: 0 | Q15: 17198000 | R15: Export - WOP - Amount received after September | S15: Considered in ZRT
A16: 45839 | B16: SSPL/07-25EX/1 | C16: 45868 | D16: SS USA Inc | E16: Export - Without payment of tax | F16: USA | G16: Unregistered | H16: 998313 | I16: USD | J16: 86.92 | K16: 50000 | L16: 4346000 | M16: 0 | N16: 0 | O16: 0 | P16: 0 | Q16: 4346000 | R16: Export - WOP - Amount received after September | S16: Considered in ZRT
A17: 45839 | B17: SSPL/07-25EX/3 | C17: 45869 | D17: SS USA Inc | E17: Export - Without payment of tax | F17: USA | G17: Unregistered | H17: 998313 | I17: USD | J17: 87.43 | K17: 120000 | L17: 10491600 | M17: 0 | N17: 0 | O17: 0 | P17: 0 | Q17: 10491600 | R17: Export - WOP - Amount received after September | S17: Considered in ZRT
... A32: 45901 | B32: SSPL/09-25EX/6 | C32: 45930 | D32: SS USA Inc | E32: Export - Without payment of tax | F32: USA | G32: Unregistered | H32: 998313 | I32: USD | J32: 88.7083 | K32: 120000 | L32: 10644996 | M32: 0 | N32: 0 | O32: 0 | P32: 0 | Q32: 10644996 | R32: Export - WOP - Amount received after September | S32: Not Considered in ZRT

Sheet Sales Vs FIRC 
A1: Softdel System Limited Refund Working
A2: FIRC Summary
A3: Period: October-25 to December-25
I4: =SUBTOTAL(9,I6:I1048576) -> 125640150 | N4: =SUBTOTAL(9,N6:N1048576) -> 125640150 | P4: =SUBTOTAL(9,P6:P1048576) -> 125640150 | Q4: =SUBTOTAL(9,Q6:Q1048576) -> 0 | S4: =N4-P4 -> 0
A5: - | B5: SR No. | C5: Client Name | D5: Invoice Number | E5: Invoice Date | F5: Nature of Service (Description) | G5: Currency of Invoice | H5: Invoice Amount in Foreign Currency | I5: Export Value in INR | J5: FIRC No. | K5: Date of Receipt | L5: FIRC Amount in Foreign Currency | M5: Exchange Rate | N5: Collection Amount in INR | P5: Check | Q5: -
B6: 1 | C6: SS USA Inc | D6: SSPL/04-25Ex/04 | E6: 45777 | G6: USD | H6: 120000 | I6: 10219200 | J6: 0209GRSJ25075560 | K6: 45947 | L6: 109965 | M6: 87.8 | N6: 9654927
J7: 0209GRSJ25084454 | K7: 45954 | L7: =N7/M7 -> 6431.9275 | M7: 87.73 | N7: =I6-N6 -> 564273 | P7: =N7+N6 -> 10219200 | Q7: =P7-I6 -> 0
B8: 2 | C8: SS USA Inc | D8: SSPL/04-25Ex/05 | E8: 45777 | G8: USD | H8: 130000 | I8: 11070800 | J8: 0209GRSJ25084454 | K8: 45954 | L8: =N8/M8 -> 113533.07 | M8: 87.73 | N8: ='FIRC Register'!F5-'Sales Vs FIRC '!N7 -> 9960256.4
J9: 0209GRSJ25083190 | K9: 45954 | L9: =N9/M9 -> 12658.652 | M9: 87.73 | N9: =I8-N8 -> 1110543.6 | P9: =N9+N8 -> 11070800 | Q9: =P9-I8 -> 0
B10: 3 | C10: SS USA Inc | D10: SSPL/05-25EX/1 | E10: 45806 | G10: USD | H10: 60000 | I10: 5125200 | J10: 0209GRSJ25083190 | K10: 45954 | L10: =N10/M10 -> 58420.153 | M10: 87.73 | N10: 5125200 | P10: =N10 -> 5125200 | Q10: =P10-I10 -> 0
B11: 4 | C11: SS USA Inc | D11: SSPL/05-25EX/2 | E11: 45808 | G11: USD | H11: 120000 | I11: 10256628 | J11: 0209GRSJ25083190 | K11: 45954 | L11: =N11/M11 -> 48886.195 | M11: 87.73 | N11: ='FIRC Register'!F6-'Sales Vs FIRC '!N10-'Sales Vs FIRC '!N9 -> 4288785.9
J12: 0209GRSJ25137046 | K12: 45961 | L12: =N12/M12 -> 67311.551 | M12: 88.66 | N12: =I11-N11 -> 5967842.1 | P12: =N12+N11 -> 10256628 | Q12: =P12-I11 -> 0
B13: 5 | C13: SS USA Inc | D13: SSPL/05-25EX/3 | E13: 45808 | G13: USD | H13: 120000 | I13: 10256628 | J13: 0209GRSJ25137046 | K13: 45961 | L13: =N13/M13 -> 42653.449 | M13: 88.66 | N13: ='FIRC Register'!F7-'Sales Vs FIRC '!N12 -> 3781654.8
J14: 0209GRSK25026388 | K14: 45968 | L14: =N14/M14 -> 73080.962 | M14: 88.6 | N14: =I13-N13 -> 6474973.2 | P14: =N14+N13 -> 10256628 | Q14: =P14-I13 -> 0
B15: 6 | C15: SS USA Inc | D15: SSPL/05-25EX/4 | E15: 45808 | G15: USD | H15: 130000 | I15: 11111347 | J15: 0209GRSK25026388 | K15: 45968 | L15: =N15/M15 -> 46884.038 | M15: 88.6 | N15: ='FIRC Register'!F9-'Sales Vs FIRC '!N14 -> 4153925.8
J16: 0209GRSK25026433 | K16: 45968 | L16: =N16/M16 -> 78526.199 | M16: 88.6 | N16: =I15-N15 -> 6957421.2 | P16: =N16+N15 -> 11111347 | Q16: =P16-I15 -> 0
B17: 7 | C17: SS USA Inc | D17: SSPL/05-25EX/5 | E17: 45808 | G17: USD | H17: 130000 | I17: 11111347 | J17: 0209GRSK25026433 | K17: 45968 | L17: =N17/M17 -> 31438.801 | M17: 88.6 | N17: ='FIRC Register'!F10-'Sales Vs FIRC '!N16 -> 2785477.8
J18: 0209GRSK25064826 | K18: 45978 | L18: =N18/M18 -> 94066.989 | M18: 88.51 | N18: =I17-N17 -> 8325869.2 | P18: =N18+N17 -> 11111347 | Q18: =P18-I17 -> 0
B19: 8 | C19: SS USA Inc | D19: SSPL/06-25Ex/1 | E19: 45811 | G19: USD | H19: 175000 | I19: 14945000 | J19: 0209GRSK25064826 | K19: 45978 | L19: =N19/M19 -> 25898.011 | M19: 88.51 | N19: ='FIRC Register'!F12-'Sales Vs FIRC '!N18 -> 2292232.9
J20: 0209GRSK25064780 | K20: 45978 | L20: =N20/M20 -> 99965 | M20: 88.51 | N20: ='FIRC Register'!F13 -> 8847902.2
J21: 0209GRSK25083734 | K21: 45981 | L21: =N21/M21 -> 42915.237 | M21: 88.66 | N21: =I19-N20-N19 -> 3804864.9 | P21: =N21+N20+N19 -> 14945000 | Q21: =P21-I19 -> 0
B22: 9 | C22: SS USA Inc | D22: SSPL/06-25EX/2 | E22: 45827 | G22: USD | H22: 110000 | I22: 9508400 | J22: 0209GRSK25083734 | K22: 45981 | L22: =N22/M22 -> 37049.763 | M22: 88.66 | N22: ='FIRC Register'!F14-'Sales Vs FIRC '!N21 -> 3284832
J23: 0209GRSL25010603 | K23: 45994 | L23: =N23/M23 -> 69089.343 | M23: 90.08 | N23: =I22-N22 -> 6223568 | P23: =N23+N22 -> 9508400 | Q23: =P23-I22 -> 0
B24: 10 | C24: SS USA Inc | D24: SSPL/06-25EX/3 | E24: 45834 | G24: USD | H24: 200000 | I24: 17198000 | J24: 0209GRSL25010603 | K24: 45994 | L24: =N24/M24 -> 80875.657 | M24: 90.08 | N24: ='FIRC Register'!F15-'Sales Vs FIRC '!N23 -> 7285279.2
J25: 0209GRSL25060277 | K25: 46003 | L25: =N25/M25 -> 109799.74 | M25: 90.28 | N25: =I24-N24 -> 9912720.8 | P25: =N25+N24 -> 17198000 | Q25: =P25-I24 -> 0
B26: 11 | C26: SS USA Inc | D26: SSPL/07-25EX/1 | E26: 45868 | G26: USD | H26: 50000 | I26: 4346000 | J26: 0209GRSL25060277 | K26: 46003 | L26: =N26/M26 -> 40165.257 | M26: 90.28 | N26: ='FIRC Register'!F16-'Sales Vs FIRC '!N25 -> 3626119.4
J27: 0209GRSL25080255 | K27: 46008 | L27: =N27/M27 -> 7998.6733 | M27: 90 | N27: =I26-N26 -> 719880.6 | P27: =N27+N26 -> 4346000 | Q27: =P27-I26 -> 0
B28: 12 | C28: SS USA Inc | D28: SSPL/07-25EX/3 | E28: 45869 | G28: USD | H28: 120000 | I28: 10491600 | J28: 0209GRSL25080255 | K28: 46008 | L28: =N28/M28 -> 116573.33 | M28: 90 | N28: =I28 -> 10491600 | P28: =N28 -> 10491600 | Q28: =P28-I28 -> 0

Sheet FIRC Register
A1: Softdel System Limited Refund Working
F2: =SUBTOTAL(9,F4:F1048576) -> 2.5812112e+08
A3: Sr No | B3: No. | C3: Date (dd-mm-yyyy) | D3: Currency | E3: Amount in Foreign Currency | F3: Value (In INR) | G3: Bank Name | H3: - | I3: Rate | J3: Remarks
A4: 1 | B4: 0209GRSJ25075560 | C4: 45947 | D4: USD | E4: 109965 | F4: 9654927 | I4: 87.8 | J4: Utilised
A5: =A4+1 -> 2 | B5: 0209GRSJ25084454 | C5: 45954 | D5: USD | E5: 119965 | F5: 10524529 | I5: 87.73 | J5: Utilised
A6: =A5+1 -> 3 | B6: 0209GRSJ25083190 | C6: 45954 | D6: USD | E6: 119965 | F6: 10524529 | I6: 87.73 | J6: Utilised
A7: =A6+1 -> 4 | B7: 0209GRSJ25137046 | C7: 45961 | D7: USD | E7: 109965 | F7: 9749496.9 | I7: 88.66 | J7: Utilised
A8: =A7+1 -> 5 | B8: 0209GRSK25013366 | C8: 45967 | D8: JPY | E8: 12000000 | F8: 6780000 | I8: 0.565 | J8: Not utilized as payment received from Japan.
A9: =A8+1 -> 6 | B9: 0209GRSK25026388 | C9: 45968 | D9: USD | E9: 119965 | F9: 10628899 | I9: 88.6 | J9: Utilised
A10: =A9+1 -> 7 | B10: 0209GRSK25026433 | C10: 45968 | D10: USD | E10: 109965 | F10: 9742899 | I10: 88.6 | J10: Utilised
A11: =A10+1 -> 8 | B11: 0209GRSK25049558 | C11: 45974 | D11: JPY | E11: 10000000 | F11: 5590000 | I11: 0.559 | J11: Not utilized as payment received from Japan.
A12: =A11+1 -> 9 | B12: 0209GRSK25064826 | C12: 45978 | D12: USD | E12: 119965 | F12: 10618102 | I12: 88.51 | J12: Utilised
A13: =A12+1 -> 10 | B13: 0209GRSK25064780 | C13: 45978 | D13: USD | E13: 99965 | F13: 8847902.2 | I13: 88.51 | J13: Utilised
A14: =A13+1 -> 11 | B14: 0209GRSK25083734 | C14: 45981 | D14: USD | E14: 79965 | F14: 7089696.9 | I14: 88.66 | J14: Utilised
A15: =A14+1 -> 12 | B15: 0209GRSL25010603 | C15: 45994 | D15: USD | E15: 149965 | F15: 13508847 | I15: 90.08 | J15: Utilised
A16: =A15+1 -> 13 | B16: 0209GRSL25060277 | C16: 46003 | D16: USD | E16: 149965 | F16: 13538840 | I16: 90.28 | J16: Utilised
... A28: =A27+1 -> 25 | B28: 0209GRSC26018580 | C28: 46086 | D28: USD | E28: 129965 | F28: 11895696 | I28: 91.53 | J28: Not utilized

Sheet statement 3
A1: Goods and Services Tax
A4: Statement-3 [rule 89(2) (b) & 89(2)(c)]
A6: * Indicates Mandatory Fields | C6: GSTIN* | D6: 27AAECS0576Q1ZQ | M6: * Indicates Mandatory Fields
A7: From Return Period* (mmyyyy) | D7: 102025 | G7: Refund Type: Export without payment of tax (accumulated ITC) | M7: * Please use clear from drop down to delete. Do not hard delete the contents
A8: To Return Period* (mmyyyy) | D8: 122025
A9: ***Note:- These sheet at a time can take upto 10,000 rows / entries Kindly download the latest version of offline utility for preparing and uploading the statement on GST portal. Else you may face issues while uploading the statement prepared using the old version
A10: Sr. No. | B10: Document Details | F10: Goods/ Services (G/S) | G10: Shipping bill/ Bill of export/ Endorsed invoice no. | K10: EGM Details | M10: BRC/ FIRC | P10: Error
B11: Type of Document | C11: No. | D11: Date (dd-mm-yyyy) | E11: Value | G11: Port Code | H11: No. | I11: Date (dd-mm-yyyy) | J11: FOB Value | K11: Ref No. | L11: Date (dd-mm-yyyy) | M11: No. | N11: Date (dd-mm-yyyy) | O11: Value
A12: 1 | B12: 2 | C12: 3 | D12: 4 | E12: 5 | F12: 6 | G12: 7 | H12: 8 | I12: 9 | J12: 10 | K12: 11 | L12: 12 | M12: 13 | N12: 14 | O12: 15 | P12: 16
A13: 1 | B13: Invoice | C13: SSPL/04-25Ex/04 | D13: 45777 | E13: 10219200 | F13: S | M13: 0209GRSJ25075560 | N13: 45947 | O13: 9654927
A14: =A13+1 -> 2 | B14: Invoice | C14: SSPL/04-25Ex/05 | D14: 45777 | E14: 11070800 | F14: S | M14: 0209GRSJ25084454 | N14: 45954 | O14: 10524529
A15: =A14+1 -> 3 | B15: Invoice | C15: SSPL/05-25EX/1 | D15: 45806 | E15: 5125200 | F15: S | M15: 0209GRSJ25083190 | N15: 45954 | O15: 10524529
A16: =A15+1 -> 4 | B16: Invoice | C16: SSPL/05-25EX/2 | D16: 45808 | E16: 10256628 | F16: S | M16: 0209GRSJ25137046 | N16: 45961 | O16: 9749496.9
A17: =A16+1 -> 5 | B17: Invoice | C17: SSPL/05-25EX/3 | D17: 45808 | E17: 10256628 | F17: S | M17: 0209GRSK25026388 | N17: 45968 | O17: 10628899
A18: =A17+1 -> 6 | B18: Invoice | C18: SSPL/05-25EX/4 | D18: 45808 | E18: 11111347 | F18: S | M18: 0209GRSK25026433 | N18: 45968 | O18: 9742899
A19: =A18+1 -> 7 | B19: Invoice | C19: SSPL/05-25EX/5 | D19: 45808 | E19: 11111347 | F19: S | M19: 0209GRSK25064826 | N19: 45978 | O19: 10618102
A20: =A19+1 -> 8 | B20: Invoice | C20: SSPL/06-25Ex/1 | D20: 45811 | E20: 14945000 | F20: S | M20: 0209GRSK25064780 | N20: 45978 | O20: 8847902.2
A21: =A20+1 -> 9 | B21: Invoice | C21: SSPL/06-25EX/2 | D21: 45827 | E21: 9508400 | F21: S | M21: 0209GRSK25083734 | N21: 45981 | O21: 7089696.9
A22: =A21+1 -> 10 | B22: Invoice | C22: SSPL/06-25EX/3 | D22: 45834 | E22: 17198000 | F22: S | M22: 0209GRSL25010603 | N22: 45994 | O22: 13508847
A23: =A22+1 -> 11 | B23: Invoice | C23: SSPL/07-25EX/1 | D23: 45868 | E23: 4346000 | F23: S | M23: 0209GRSL25060277 | N23: 46003 | O23: 13538840
A24: =A23+1 -> 12 | B24: Invoice | C24: SSPL/07-25EX/3 | D24: 45869 | E24: 10491600 | F24: S | M24: 0209GRSL25080255 | N24: 46008 | O24: 13496850

Sheet Monthly Return Summary
B3: Sales as per GSTR-1 - Oct-25 | G3: Sales as per GSTR-1 - Nov-25 | L3: Sales as per GSTR-1 - Dec-25 | R3: Total
A4: Type of Sales | B4: Taxable Value | C4: IGST | D4: CGST | E4: SGST | G4: Taxable Value | H4: IGST | I4: CGST | J4: SGST | L4: Taxable Value | M4: IGST | N4: CGST | O4: SGST | R4: Taxable Value | S4: IGST | T4: CGST | U4: SGST
A5: 1. Domestic Sales (Net of Credit Notes) | B5: 2998227 | C5: 0 | D5: 269840.43 | E5: 269840.43 | G5: 2986234 | H5: 45000 | I5: 246261.06 | J5: 246261.06 | L5: 3694736 | M5: 0 | N5: 332526.24 | O5: 332526.24 | R5: =B5+G5+L5 -> 9679197 | S5: =C5+H5+M5 -> 45000 | T5: =D5+I5+N5 -> 848627.73 | U5: =E5+J5+O5 -> 848627.73
A6: 2. Exempt Sales (Net of Credit Notes) | B6: 9860000 | C6: 0 | D6: 0 | E6: 0 | G6: 5700000 | H6: 0 | I6: 0 | J6: 0 | L6: 10440000 | M6: 0 | N6: 0 | O6: 0 | R6: =B6+G6+L6 -> 26000000 | S6: =C6+H6+M6 -> 0 | T6: =D6+I6+N6 -> 0 | U6: =E6+J6+O6 -> 0
A7: 3. Export Sales (WOP) - (Net of Credit Notes) | B7: 51370368 | C7: 0 | D7: 0 | E7: 0 | G7: 51766000 | H7: 0 | I7: 0 | J7: 0 | L7: 44917052 | M7: 0 | N7: 0 | O7: 0 | R7: =B7+G7+L7 -> 148053420 | S7: =C7+H7+M7 -> 0 | T7: =D7+I7+N7 -> 0 | U7: =E7+J7+O7 -> 0
A8: 4. B2B Credit note | B8: 0 | C8: 0 | D8: 0 | E8: 0 | G8: 0 | H8: 0 | I8: 0 | J8: 0 | L8: -816640 | M8: 0 | N8: -73497.6 | O8: -73497.6 | R8: =B8+G8+L8 -> -816640 | S8: =C8+H8+M8 -> 0 | T8: =D8+I8+N8 -> -73497.6 | U8: =E8+J8+O8 -> -73497.6
A9: 5. SEZ - Without payment of tax | B9: 0 | C9: 0 | D9: 0 | E9: 0 | G9: 0 | H9: 0 | I9: 0 | J9: 0 | L9: 0 | M9: 0 | N9: 0 | O9: 0 | R9: =B9+G9+L9 -> 0 | S9: =C9+H9+M9 -> 0 | T9: =D9+I9+N9 -> 0 | U9: =E9+J9+O9 -> 0
A10: Grand Total | B10: =SUM(B5:B9) -> 64228595 | C10: =SUM(C5:C9) -> 0 | D10: =SUM(D5:D9) -> 269840.43 | E10: =SUM(E5:E9) -> 269840.43 | G10: =SUM(G5:G9) -> 60452234 | H10: =SUM(H5:H9) -> 45000 | I10: =SUM(I5:I9) -> 246261.06 | J10: =SUM(J5:J9) -> 246261.06 | L10: =SUM(L5:L9) -> 58235148 | M10: =SUM(M5:M9) -> 0 | N10: =SUM(N5:N9) -> 259028.64 | O10: =SUM(O5:O9) -> 259028.64 | R10: =SUM(R5:R9) -> 182915977 | S10: =SUM(S5:S9) -> 45000 | T10: =SUM(T5:T9) -> 775130.13 | U10: =SUM(U5:U9) -> 775130.13
R11: =R10-R6 -> 156915977 | S11: =S10-S6 -> 45000 | T11: =T10-T6 -> 775130.13 | U11: =U10-U6 -> 775130.13
B12: Sales as per GSTR-3B - Oct-25 | G12: Sales as per GSTR-3B - Nov-25 | L12: Sales as per GSTR-3B - Dec-25 | R12: Total
A13: Type of Sales | B13: Taxable Value | C13: IGST | D13: CGST | E13: SGST | G13: Taxable Value | H13: IGST | I13: CGST | J13: SGST | L13: Taxable Value | M13: IGST | N13: CGST | O13: SGST | R13: Taxable Value | S13: IGST | T13: CGST | U13: SGST
A14: 1. Outward supplies (other than zero rated, nil rated and exempted) | B14: 2998227 | C14: 0 | D14: 269840.43 | E14: 269840.43 | G14: 2986234 | H14: 45000 | I14: 246261.06 | J14: 246261.06 | L14: 2878096 | M14: 0 | N14: 259029 | O14: 259029 | R14: =B14+G14+L14 -> 8862557 | S14: =C14+H14+M14 -> 45000 | T14: =D14+I14+N14 -> 775130.49 | U14: =E14+J14+O14 -> 775130.49
A15: 2. Outward taxable supplies (zero rated) | B15: 51370368 | C15: 0 | D15: 0 | E15: 0 | G15: 51766000 | H15: 0 | I15: 0 | J15: 0 | L15: 44917052 | M15: 0 | N15: 0 | O15: 0 | R15: =B15+G15+L15 -> 148053420 | S15: =C15+H15+M15 -> 0 | T15: =D15+I15+N15 -> 0 | U15: =E15+J15+O15 -> 0
A16: 3. Other outward supplies (nil rated, exempted) | B16: 9860000 | C16: 0 | D16: 0 | E16: 0 | G16: 5700000 | H16: 0 | I16: 0 | J16: 0 | L16: 10440000 | M16: 0 | N16: 0 | O16: 0 | R16: =B16+G16+L16 -> 26000000 | S16: =C16+H16+M16 -> 0 | T16: =D16+I16+N16 -> 0 | U16: =E16+J16+O16 -> 0
A17: Grand Total | B17: =SUM(B14:B16) -> 64228595 | C17: =SUM(C14:C16) -> 0 | D17: =SUM(D14:D16) -> 269840.43 | E17: =SUM(E14:E16) -> 269840.43 | G17: =SUM(G14:G16) -> 60452234 | H17: =SUM(H14:H16) -> 45000 | I17: =SUM(I14:I16) -> 246261.06 | J17: =SUM(J14:J16) -> 246261.06 | L17: =SUM(L14:L16) -> 58235148 | M17: =SUM(M14:M16) -> 0 | N17: =SUM(N14:N16) -> 259029 | O17: =SUM(O14:O16) -> 259029 | R17: =SUM(R14:R16) -> 182915977 | S17: =SUM(S14:S16) -> 45000 | T17: =SUM(T14:T16) -> 775130.49 | U17: =SUM(U14:U16) -> 775130.49
B19: Purchase as per GSTR-3B - Oct-25 | G19: Purchase as per GSTR-3B - Nov-25 | L19: Purchase as per GSTR-3B - Dec-25 | R19: Total
A20: Type of Purchase | B20: Taxable Value | C20: IGST | D20: CGST | E20: SGST | G20: Taxable Value | H20: IGST | I20: CGST | J20: SGST | L20: Taxable Value | M20: IGST | N20: CGST | O20: SGST | R20: Taxable Value | S20: IGST | T20: CGST | U20: SGST
A21: 1. + IMPG | R21: =B21+G21+L21 -> 0 | S21: =C21+H21+M21 -> 0 | T21: =D21+I21+N21 -> 0 | U21: =E21+J21+O21 -> 0
A22: 2. + IMPS | C22: 20740 | H22: 83937 | M22: 29481 | R22: =B22+G22+L22 -> 0 | S22: =C22+H22+M22 -> 134158 | T22: =D22+I22+N22 -> 0 | U22: =E22+J22+O22 -> 0
A23: 3. + RCM - Domestic | I23: 1305 | J23: 1305 | R23: =B23+G23+L23 -> 0 | S23: =C23+H23+M23 -> 0 | T23: =D23+I23+N23 -> 1305 | U23: =E23+J23+O23 -> 1305
A24: 4. + All Other ITC | C24: 832681 | D24: 1263634 | E24: 1263634 | H24: 218989 | I24: 1194899 | J24: 1194899 | M24: 381595 | N24: 2315218 | O24: 2315218 | R24: =B24+G24+L24 -> 0 | S24: =C24+H24+M24 -> 1433265 | T24: =D24+I24+N24 -> 4773751 | U24: =E24+J24+O24 -> 4773751
A25: 5. - Reversal u/s 17(5) | C25: -114863 | D25: -149966 | E25: -149966 | H25: -22721 | I25: -84940 | J25: -84940 | M25: -48492 | N25: -220162 | O25: -220162 | R25: =B25+G25+L25 -> 0 | S25: =C25+H25+M25 -> -186076 | T25: =D25+I25+N25 -> -455068 | U25: =E25+J25+O25 -> -455068
A26: 6. - Other Reversals | C26: -105195 | D26: -293749 | E26: -293749 | H26: -61960 | I26: -488735 | J26: -488735 | M26: -140582 | N26: -1096190 | O26: -1096190 | R26: =B26+G26+L26 -> 0 | S26: =C26+H26+M26 -> -307737 | T26: =D26+I26+N26 -> -1878674 | U26: =E26+J26+O26 -> -1878674
A27: Net ITC Availed | B27: =SUM(B21:B26) -> 0 | C27: =SUM(C21:C26) -> 633363 | D27: =SUM(D21:D26) -> 819919 | E27: =SUM(E21:E26) -> 819919 | G27: =SUM(G21:G26) -> 0 | H27: =SUM(H21:H26) -> 218245 | I27: =SUM(I21:I26) -> 622529 | J27: =SUM(J21:J26) -> 622529 | L27: =SUM(L21:L26) -> 0 | M27: =SUM(M21:M26) -> 222002 | N27: =SUM(N21:N26) -> 998866 | O27: =SUM(O21:O26) -> 998866 | R27: =SUM(R21:R26) -> 0 | S27: =SUM(S21:S26) -> 1073610 | T27: =SUM(T21:T26) -> 2441314 | U27: =SUM(U21:U26) -> 2441314 | V27: =SUM(R27:U27) -> 5956238
C29: -1
C30: -1

Sheet Annexure-B
A1: Softdel Systems Private Limited
A2: Annexure-B | D2: ACN2526000058808
I3: =SUBTOTAL(9,I7:I901) -> 2441313.7 | J3: =SUBTOTAL(9,J7:J901) -> 2441313.7 | K3: =SUBTOTAL(9,K7:K901) -> 1073609.1 | N3: =SUBTOTAL(9,N7:N901) -> 5956236.5
A4: Sr No. | B4: GSTIN of the supplier | C4: Name of the Supplier | D4: Invoice details | G4: Category of inputs supplies | I4: Central Tax | J4: State tax/Union Territory tax | K4: Integrated tax | L4: Cess | M4: Eligible for ITC | N4: Amount of Eligible ITC | O4: Months in GSTR-3B | P4: Serial Number in GSTR-2B | Q4: Months in GSTR-2B | R4: Remarks
D5: Invoice No. | E5: Date | F5: Invoice Value | G5: Inputs/Inputs Services/capital goods | H5: HSN/SAC | M5: Yes/No/Partially
A6: 1 | B6: 2 | C6: 3 | D6: 4 | E6: 5 | F6: 6 | G6: 7 | H6: 8 | I6: 9 | J6: 10 | K6: 11 | L6: 12 | M6: 13 | N6: 14 | O6: 15 | P6: 16 | Q6: 17 | R6: 18
A7: 1 | B7: IMPS | C7: Zoom Video Communications Inc. | D7: INV325785229 | E7: 45944 | F7: 984 | G7: Input Service | H7: 0 | I7: 0 | J7: 0 | K7: 150 | L7: 0 | M7: Yes | N7: 150 | O7: 45931 | P7: IMPS | Q7: 45931 | R7: IMPS
A8: 2 | B8: IMPS | C8: GitHub, Inc. | D8: INV102317885 | E8: 45931 | F8: 88626 | G8: Input Service | H8: 0 | I8: 0 | J8: 0 | K8: 13519 | L8: 0 | M8: Yes | N8: 13519 | O8: 45931 | P8: IMPS | Q8: 45931 | R8: IMPS
A9: 3 | B9: IMPS | C9: GitHub, Inc. | D9: INV101861196 | E9: 45928 | F9: 4774 | G9: Input Service | H9: 0 | I9: 0 | J9: 0 | K9: 728 | L9: 0 | M9: Yes | N9: 728 | O9: 45931 | P9: IMPS | Q9: 45931 | R9: IMPS
A10: 4 | B10: IMPS | C10: GitHub, Inc. | D10: INV101864279 | E10: 45928 | F10: 11719 | G10: Input Service | H10: 0 | I10: 0 | J10: 0 | K10: 1788 | L10: 0 | M10: Yes | N10: 1788 | O10: 45931 | P10: IMPS | Q10: 45931 | R10: IMPS
A11: 5 | B11: IMPS | C11: GitHub, Inc. | D11: INV103201239 | E11: 45938 | F11: 11340 | G11: Input Service | H11: 0 | I11: 0 | J11: 0 | K11: 1730 | L11: 0 | M11: Yes | N11: 1730 | O11: 45931 | P11: IMPS | Q11: 45931 | R11: IMPS
A12: 6 | B12: IMPS | C12: GitHub, Inc. | D12: INV103796429 | E12: 45943 | F12: 216 | G12: Input Service | H12: 0 | I12: 0 | J12: 0 | K12: 33 | L12: 0 | M12: Yes | N12: 33 | O12: 45931 | P12: IMPS | Q12: 45931 | R12: IMPS
A13: 7 | B13: IMPS | C13: Zoom Video Communications Inc. | D13: INV325267738 | E13: 45940 | F13: 18301 | G13: Input Service | H13: 0 | I13: 0 | J13: 0 | K13: 2792 | L13: 0 | M13: Yes | N13: 2792 | O13: 45931 | P13: IMPS | Q13: 45931 | R13: IMPS
A14: 8 | B14: 27AASCS3903K1ZV | C14: SEMSYS PRIVATE LIMITED | D14: 2526350 | E14: 01/10/2025 | F14: 11564 | G14: Input Service | H14: 998332 | I14: 882 | J14: 882 | K14: 0 | L14: 0 | M14: No | N14: 1764 | O14: 45931 | P14: 2596 | Q14: 45931 | R14: All other ITC
A15: 9 | B15: 27AASCS3903K1ZV | C15: SEMSYS PRIVATE LIMITED | D15: 2526351 | E15: 01/10/2025 | F15: 9440 | G15: Input Service | H15: 998332 | I15: 720 | J15: 720 | K15: 0 | L15: 0 | M15: No | N15: 1440 | O15: 45931 | P15: 2597 | Q15: 45931 | R15: All other ITC
A16: 10 | B16: 27AASCS3903K1ZV | C16: SEMSYS PRIVATE LIMITED | D16: 2526352 | E16: 01/10/2025 | F16: 9440 | G16: Input Service | H16: 998332 | I16: 720 | J16: 720 | K16: 0 | L16: 0 | M16: No | N16: 1440 | O16: 45931 | P16: 2598 | Q16: 45931 | R16: All other ITC
A17: 11 | B17: 27AASCS3903K1ZV | C17: SEMSYS PRIVATE LIMITED | D17: 2526353 | E17: 01/10/2025 | F17: 4720 | G17: Input Service | H17: 998332 | I17: 360 | J17: 360 | K17: 0 | L17: 0 | M17: No | N17: 720 | O17: 45931 | P17: 2599 | Q17: 45931 | R17: All other ITC
A18: 12 | B18: 27AASCS3903K1ZV | C18: SEMSYS PRIVATE LIMITED | D18: 2526354 | E18: 01/10/2025 | F18: 4720 | G18: Input Service | H18: 998332 | I18: 360 | J18: 360 | K18: 0 | L18: 0 | M18: No | N18: 720 | O18: 45931 | P18: 2600 | Q18: 45931 | R18: All other ITC
A19: 13 | B19: 27AASCS3903K1ZV | C19: SEMSYS PRIVATE LIMITED | D19: 2526355 | E19: 01/10/2025 | F19: 23600 | G19: Input Service | H19: 998332 | I19: 1800 | J19: 1800 | K19: 0 | L19: 0 | M19: No | N19: 3600 | O19: 45931 | P19: 2601 | Q19: 45931 | R19: All other ITC
A20: 14 | B20: 27AAGCR8772D1Z2 | C20: Porter | D20: CRN1267653331 | E20: 30/09/2025 | F20: 118 | G20: Input Service | H20: 996511 | I20: 9 | J20: 9 | K20: 0 | L20: 0 | M20: No | N20: 18 | O20: 45931 | P20: 877 | Q20: 45931 | R20: All other ITC
A21: 15 | B21: 27AIFPK3096H1Z3 | C21: RAJ ELECTRICALS | D21: 63210 | E21: 10/10/2025 | F21: 413 | G21: Inputs | H21: 0 | I21: 31.5 | J21: 31.5 | K21: 0 | L21: 0 | M21: No | N21: 63 | O21: 45931 | P21: 2728 | Q21: 45931 | R21: All other ITC
A22: 16 | B22: 27AAMFD2812K1ZC | C22: DESIGNSTYLE STUDIOS | D22: 69 | E22: 11/08/2025 | F22: 1770 | H22: 0 | I22: 135 | J22: 135 | K22: 0 | L22: 0 | M22: No | N22: 270 | O22: 45931 | P22: 2724 | Q22: 45931 | R22: All other ITC
A23: 17 | B23: 03ACCPS7232A1Z5 | C23: ELECTRO SALES | D23: ES-ECOM-179 | E23: 06/10/2025 | F23: 1330 | H23: 0 | I23: 0 | J23: 0 | K23: 202.88 | L23: 0 | M23: No | N23: 202.88 | O23: 45931 | P23: 2605 | Q23: 45931 | R23: All other ITC
A24: 18 | B24: 27AAACU4322N1Z6 | C24: UPS EXPRESS PRIVATE LIMITED | D24: 427100363393 | E24: 29/10/2025 | F24: 5272.24 | G24: Input Service | H24: 996813 | I24: 402.12 | J24: 402.12 | K24: 0 | L24: 0 | M24: No | N24: 804.24 | O24: 45931 | P24: 2723 | Q24: 45931 | R24: All other ITC
